Workbook

Sheet 客户方案计算表
B1: 2020.8.19日及之前的利率核算表 | H1: 2020.8.20日及之后的利率核算表
A2: 使用说明 | B2: 手动填写第一行数据 | C2: 还款期数为2020.8.19日及之前期数 此列需要手动填写 | D2: 计息本金*24%/12 此列为公式,不要修改 | E2: 与签订合同保持一致 此列第一格需要手动填写 | F2: 此列为公式 不要修改 | H2: 手动填写第一行数据 | I2: 还款期数为2020.8.20日及之后的期数 此列需要手动填写 | J2: 计息本金*17%/12 此列为公式,不要修改 | K2: 与签订合同保持一致 此列第一格需要手动填写 | L2: 此列为公式 不要修改
B3: 计息本金 | C3: 还款期数 （合同） | D3: 每月应还利息金额 | E3: 每月还款金额 | F3: 每月应抵本金 | H3: 计息本金 | I3: 还款期数 （合同） | J3: 每月应还利息金额 | K3: 每月还款金额 | L3: 每月应抵本金 | N3: 数值对应关系 | O3: 解释
B4: 62000 | C4: 1 | D4: =B4*24%/12 -> 1240 | E4: 2528.68 | F4: =E4-D4 -> 1288.68 | G4: 8.22 | H4: =B20 -> 37979.926 | I4: 17 | J4: =H4*17%/12 -> 538.04895 | K4: =E4 -> 2528.68 | L4: =K4-J4 -> 1990.6311 | N4: 计息本金=客户实际到账本金，不包含砍头息
B5: =B4-F4 -> 60711.32 | C5: 2 | D5: =B5*24%/12 -> 1214.2264 | E5: =$E$4 -> 2528.68 | F5: =E5-D5 -> 1314.4536 | G5: 9.22 | H5: =H4-L4 -> 35989.295 | I5: 18 | J5: =H5*17%/12 -> 509.84834 | K5: =$E$4 -> 2528.68 | L5: =K5-J5 -> 2018.8317 | N5: 每月应还利息=计息本金*17%/12 | O5: 每个月客户按17%应该还的利息
B6: =B5-F5 -> 59396.866 | C6: 3 | D6: =B6*24%/12 -> 1187.9373 | E6: =$E$4 -> 2528.68 | F6: =E6-D6 -> 1340.7427 | G6: 10.22 | H6: =H5-L5 -> 33970.463 | I6: 19 | J6: =H6*17%/12 -> 481.24823 | K6: =$E$4 -> 2528.68 | L6: =K6-J6 -> 2047.4318 | N6: 每月还款金额=合同约定还款金额
B7: =B6-F6 -> 58056.124 | C7: 4 | D7: =B7*24%/12 -> 1161.1225 | E7: =$E$4 -> 2528.68 | F7: =E7-D7 -> 1367.5575 | G7: 11.22 | H7: =H6-L6 -> 31923.031 | I7: 20 | J7: =H7*17%/12 -> 452.24294 | K7: =$E$4 -> 2528.68 | L7: =K7-J7 -> 2076.4371 | N7: 每月应抵本金=还款金额-应还利息金额
B8: =B7-F7 -> 56688.566 | C8: 5 | D8: =B8*24%/12 -> 1133.7713 | E8: =$E$4 -> 2528.68 | F8: =E8-D8 -> 1394.9087 | G8: 12.22 | H8: =H7-L7 -> 29846.594 | I8: 21 | J8: =H8*17%/12 -> 422.82675 | K8: =$E$4 -> 2528.68 | L8: =K8-J8 -> 2105.8532 | N8: 第二期计息本金=客户实际到账本金-应抵本金
B9: =B8-F8 -> 55293.658 | C9: 6 | D9: =B9*24%/12 -> 1105.8732 | E9: =$E$4 -> 2528.68 | F9: =E9-D9 -> 1422.8068 | G9: 1.22 | H9: =H8-L8 -> 27740.741 | I9: 22 | J9: =H9*17%/12 -> 392.99383 | K9: =$E$4 -> 2528.68 | L9: =K9-J9 -> 2135.6862 | N9: 逾期利息=剩余本金*17%/12*逾期期数 | O9: 这个利息直到客户清偿之日为止
B10: =B9-F9 -> 53870.851 | C10: 7 | D10: =B10*24%/12 -> 1077.417 | E10: =$E$4 -> 2528.68 | F10: =E10-D10 -> 1451.263 | H10: =H9-L9 -> 25605.055 | I10: 23 | J10: =H10*17%/12 -> 362.73828 | K10: =$E$4 -> 2528.68 | L10: =K10-J10 -> 2165.9417 | N10: 客户年化率，按鲸算师APP进行计算，进入APP后选择贷款利率
B11: =B10-F10 -> 52419.588 | C11: 8 | D11: =B11*24%/12 -> 1048.3918 | E11: =$E$4 -> 2528.68 | F11: =E11-D11 -> 1480.2882 | H11: =H10-L10 -> 23439.113 | I11: 24 | J11: =H11*17%/12 -> 332.0541 | K11: =$E$4 -> 2528.68 | L11: =K11-J11 -> 2196.6259 | N11: 借款总额 | O11: 客户实际到账金额
B12: =B11-F11 -> 50939.299 | C12: 9 | D12: =B12*24%/12 -> 1018.786 | E12: =$E$4 -> 2528.68 | F12: =E12-D12 -> 1509.894 | H12: =H11-L11 -> 21242.487 | I12: 25 | J12: =H12*17%/12 -> 300.93524 | K12: =$E$4 -> 2528.68 | L12: =K12-J12 -> 2227.7448
B13: =B12-F12 -> 49429.405 | C13: 10 | D13: =B13*24%/12 -> 988.58811 | E13: =$E$4 -> 2528.68 | F13: =E13-D13 -> 1540.0919 | H13: =H12-L12 -> 19014.743 | I13: 26 | J13: =H13*17%/12 -> 269.37552 | K13: =$E$4 -> 2528.68 | L13: =K13-J13 -> 2259.3045 | N13: 在进行计算时，需要了解客户合同签订时间、还款期数。从签订合同之日起至2020.8.20日，每期年化率按24%核算，2020.8.20日至还款结清月份，每期年化率按17%核算。 表格一测算的是从客户签订合同之日起至2020.8.20日，每期年化率按24%核算的结果；表格二测算的是客户从2020.8.20日至还款结清月份，每期年化率按17%核算的结果
B14: =B13-F13 -> 47889.314 | C14: 11 | D14: =B14*24%/12 -> 957.78627 | E14: =$E$4 -> 2528.68 | F14: =E14-D14 -> 1570.8937 | H14: =H13-L13 -> 16755.438 | I14: 27 | J14: =H14*17%/12 -> 237.36871 | K14: =$E$4 -> 2528.68 | L14: =K14-J14 -> 2291.3113
B15: =B14-F14 -> 46318.42 | C15: 12 | D15: =B15*24%/12 -> 926.3684 | E15: =$E$4 -> 2528.68 | F15: =E15-D15 -> 1602.3116 | H15: =H14-L14 -> 14464.127 | I15: 28 | J15: =H15*17%/12 -> 204.90846 | K15: =$E$4 -> 2528.68 | L15: =K15-J15 -> 2323.7715
B16: =B15-F15 -> 44716.108 | C16: 13 | D16: =B16*24%/12 -> 894.32216 | E16: =$E$4 -> 2528.68 | F16: =E16-D16 -> 1634.3578 | H16: =H15-L15 -> 12140.355 | I16: 29 | J16: =H16*17%/12 -> 171.98837 | K16: =$E$4 -> 2528.68 | L16: =K16-J16 -> 2356.6916
B17: =B16-F16 -> 43081.75 | C17: 14 | D17: =B17*24%/12 -> 861.63501 | E17: =$E$4 -> 2528.68 | F17: =E17-D17 -> 1667.045 | H17: =H16-L16 -> 9783.6636 | I17: 30 | J17: =H17*17%/12 -> 138.6019 | K17: =$E$4 -> 2528.68 | L17: =K17-J17 -> 2390.0781
B18: =B17-F17 -> 41414.705 | C18: 15 | D18: =B18*24%/12 -> 828.29411 | E18: =$E$4 -> 2528.68 | F18: =E18-D18 -> 1700.3859 | H18: =H17-L17 -> 7393.5855 | I18: 31 | J18: =H18*17%/12 -> 104.74246 | K18: =$E$4 -> 2528.68 | L18: =K18-J18 -> 2423.9375
A19: 7.22 | B19: =B18-F18 -> 39714.319 | C19: 16 | D19: =B19*24%/12 -> 794.28639 | E19: =$E$4 -> 2528.68 | F19: =E19-D19 -> 1734.3936 | H19: =H18-L18 -> 4969.648 | I19: 32 | J19: =H19*17%/12 -> 70.403346 | K19: =$E$4 -> 2528.68 | L19: =K19-J19 -> 2458.2767
A20: 8.22 | B20: =B19-F19 -> 37979.926 | C20: 17 | D20: =B20*24%/12 -> 759.59852 | E20: =$E$4 -> 2528.68 | F20: =E20-D20 -> 1769.0815 | H20: =H19-L19 -> 2511.3713 | I20: 33 | J20: =H20*17%/12 -> 35.57776 | K20: =$E$4 -> 2528.68 | L20: =K20-J20 -> 2493.1022
A21: 9.22 | B21: =B20-F20 -> 36210.844 | C21: 18 | D21: =B21*24%/12 -> 724.21689 | E21: =$E$4 -> 2528.68 | F21: =E21-D21 -> 1804.4631 | H21: =H20-L20 -> 18.269072 | I21: 34 | J21: =H21*17%/12 -> 0.25881185 | K21: =$E$4 -> 2528.68 | L21: =K21-J21 -> 2528.4212
B22: =B21-F21 -> 34406.381 | C22: 19 | D22: =B22*24%/12 -> 688.12763 | E22: =$E$4 -> 2528.68 | F22: =E22-D22 -> 1840.5524 | H22: =H21-L21 -> -2510.1521 | I22: 35 | J22: =H22*17%/12 -> -35.560488 | K22: =$E$4 -> 2528.68 | L22: =K22-J22 -> 2564.2405
B23: =B22-F22 -> 32565.829 | C23: 20 | D23: =B23*24%/12 -> 651.31658 | E23: =$E$4 -> 2528.68 | F23: =E23-D23 -> 1877.3634 | H23: =H22-L22 -> -5074.3926 | I23: 36 | J23: =H23*17%/12 -> -71.887229 | K23: =$E$4 -> 2528.68 | L23: =K23-J23 -> 2600.5672
B24: =B23-F23 -> 30688.465 | C24: 21 | D24: =B24*24%/12 -> 613.76931 | E24: =$E$4 -> 2528.68 | F24: =E24-D24 -> 1914.9107 | H24: =H23-L23 -> -7674.9598 | I24: 37 | J24: =H24*17%/12 -> -108.7286 | K24: =$E$4 -> 2528.68 | L24: =K24-J24 -> 2637.4086
B25: =B24-F24 -> 28773.555 | C25: 22 | D25: =B25*24%/12 -> 575.4711 | E25: =$E$4 -> 2528.68 | F25: =E25-D25 -> 1953.2089 | H25: =H24-L24 -> -10312.368 | I25: 38 | J25: =H25*17%/12 -> -146.09189 | K25: =$E$4 -> 2528.68 | L25: =K25-J25 -> 2674.7719
B26: =B25-F25 -> 26820.346 | C26: 23 | D26: =B26*24%/12 -> 536.40692 | E26: =$E$4 -> 2528.68 | F26: =E26-D26 -> 1992.2731 | H26: =H25-L25 -> -12987.14 | I26: 39 | J26: =H26*17%/12 -> -183.98449 | K26: =$E$4 -> 2528.68 | L26: =K26-J26 -> 2712.6645
B27: =B26-F26 -> 24828.073 | C27: 24 | D27: =B27*24%/12 -> 496.56146 | E27: =$E$4 -> 2528.68 | F27: =E27-D27 -> 2032.1185 | H27: =H26-L26 -> -15699.805 | I27: 40 | J27: =H27*17%/12 -> -222.4139 | K27: =$E$4 -> 2528.68 | L27: =K27-J27 -> 2751.0939
B28: =B27-F27 -> 22795.954 | C28: 25 | D28: =B28*24%/12 -> 455.91909 | E28: =$E$4 -> 2528.68 | F28: =E28-D28 -> 2072.7609 | H28: =H27-L27 -> -18450.899 | I28: 41 | J28: =H28*17%/12 -> -261.38773 | K28: =$E$4 -> 2528.68 | L28: =K28-J28 -> 2790.0677
B29: =B28-F28 -> 20723.193 | C29: 26 | D29: =B29*24%/12 -> 414.46387 | E29: =$E$4 -> 2528.68 | F29: =E29-D29 -> 2114.2161 | H29: =H28-L28 -> -21240.966 | I29: 42 | J29: =H29*17%/12 -> -300.91369 | K29: =$E$4 -> 2528.68 | L29: =K29-J29 -> 2829.5937
B30: =B29-F29 -> 18608.977 | C30: 27 | D30: =B30*24%/12 -> 372.17954 | E30: =$E$4 -> 2528.68 | F30: =E30-D30 -> 2156.5005 | H30: =H29-L29 -> -24070.56 | I30: 43 | J30: =H30*17%/12 -> -340.9996 | K30: =$E$4 -> 2528.68 | L30: =K30-J30 -> 2869.6796
B31: =B30-F30 -> 16452.477 | C31: 28 | D31: =B31*24%/12 -> 329.04954 | E31: =$E$4 -> 2528.68 | F31: =E31-D31 -> 2199.6305 | H31: =H30-L30 -> -26940.24 | I31: 44 | J31: =H31*17%/12 -> -381.6534 | K31: =$E$4 -> 2528.68 | L31: =K31-J31 -> 2910.3334
B32: =B31-F31 -> 14252.846 | C32: 29 | D32: =B32*24%/12 -> 285.05693 | E32: =$E$4 -> 2528.68 | F32: =E32-D32 -> 2243.6231 | H32: =H31-L31 -> -29850.573 | I32: 45 | J32: =H32*17%/12 -> -422.88312 | K32: =$E$4 -> 2528.68 | L32: =K32-J32 -> 2951.5631
B33: =B32-F32 -> 12009.223 | C33: 30 | D33: =B33*24%/12 -> 240.18446 | E33: =$E$4 -> 2528.68 | F33: =E33-D33 -> 2288.4955 | J33: =H33*17%/12 -> 0
B34: =B33-F33 -> 9720.7277 | C34: 31 | D34: =B34*24%/12 -> 194.41455 | E34: =$E$4 -> 2528.68 | F34: =E34-D34 -> 2334.2654 | J34: =H34*17%/12 -> 0
B35: =B34-F34 -> 7386.4622 | C35: 32 | D35: =B35*24%/12 -> 147.72924 | E35: =$E$4 -> 2528.68 | F35: =E35-D35 -> 2380.9508 | J35: =H35*17%/12 -> 0
B36: =B35-F35 -> 5005.5115 | C36: 33 | D36: =B36*24%/12 -> 100.11023 | E36: =$E$4 -> 2528.68 | F36: =E36-D36 -> 2428.5698 | J36: =H36*17%/12 -> 0
B37: =B36-F36 -> 2576.9417 | C37: 34 | D37: =B37*24%/12 -> 51.538834 | E37: =$E$4 -> 2528.68 | F37: =E37-D37 -> 2477.1412 | J37: =H37*17%/12 -> 0
B38: =B37-F37 -> 99.800553 | C38: 35 | D38: =B38*24%/12 -> 1.9960111 | E38: =$E$4 -> 2528.68 | F38: =E38-D38 -> 2526.684 | J38: =H38*17%/12 -> 0
B39: =B38-F38 -> -2426.8834 | C39: 36 | D39: =B39*24%/12 -> -48.537669 | E39: =$E$4 -> 2528.68 | F39: =E39-D39 -> 2577.2177 | J39: =H39*17%/12 -> 0
C41: 已付利息： | D41: =SUM(D4:D13)+J4 -> 11714.162 | E41: =SUM(E4:E14) -> 27815.48 | F41: =D41+J41 -> 14336.109 | I41: 未付利息： | J41: =SUM(J9:J21) -> 2621.9468
...

Sheet 逾期利息
A1: 逾期利息=剩余本金*24%/12*逾期期数 | F1: 绿色为手工填写
A2: 逾期利息=剩余本金*17%/12*逾期期数
A3: 剩余本金 | B3: 利率 | C3: 12个月 | D3: 逾期期数 | E3: 逾期利息
A4: 176284.8 | B4: 0.24 | C4: 12 | D4: 0 | E4: =A4*B4/C4*D4 -> 0
A5: 111503.15 | B5: 0.17 | C5: 12 | D5: 5 | E5: =A5*B5/C5*D5 -> 7898.1398

Sheet 减免计算
B1: 合同金额 | C1: 实际到账 | D1: 分期总数 | E1: 每期金额 | F1: 2020.8.19及之前期数 | G1: 2020.8.20及之后期数 | H1: 已还期数 | I1: 未还期数 | J1: 逾期 | K1: 应付利息 | L1: 结果
A2: 减免最大值 | B2: =客户方案计算表!E4*36 -> 91032.48 | C2: =客户方案计算表!B4 -> 62000 | D2: 36 | E2: =客户方案计算表!E4 -> 2528.68 | F2: 10 | G2: 22 | H2: 11 | I2: 21 | J2: 4 | K2: =客户方案计算表!F41 -> 14336.109 | L2: =B2-C2-客户方案计算表!D41 -> 17318.318
G3: =D3-F3 -> 0 | I3: =D3-H3 -> 0
A4: 减免最小值 | B4: =客户方案计算表!E4*36 -> 91032.48 | C4: =客户方案计算表!B4 -> 62000 | D4: 36 | E4: =客户方案计算表!E4 -> 2528.68 | F4: 10 | G4: 22 | H4: 11 | I4: 21 | J4: 4 | K4: =客户方案计算表!F41 -> 14336.109 | L4: =B4-C4-客户方案计算表!D41-客户方案计算表!J41 -> 14696.371
A21: 计算逻辑： 最大减免=合同金额-到账金额-应付利息 合同金额=每期还款*总期数 应付利息=到账金额*24%*（合同签订日期至2020年8月20日的期数）+到账金额*17*（2020年8月20日至客户最后一次还款那个月的期数） 最小减免=合同金额-到账金额-应付利息 应付利息=到账金额*24%*（合同签订日期至2020年8月20日的期数）+到账金额*17*（36-（合同签订日期至2020年8月20日的期数））
A28: 最大减免=合同金额-已还金额-核算后剩余本金 合同金额=每期还款*总期数 已还金额=每期还款*还款期数 剩余本金=实际到账金额-应付利息-冲销本金 应付利息=到账金额（剩余本金）*24%/12 剩余本金需要逐笔核减计算得出
G30: =客户方案计算表!E4*45 -> 113790.6 | I30: 最大减免 | J30: =G30-G31-G32-G33 -> 32554.897
G31: =客户方案计算表!E4*18 -> 45516.24
G32: 1749 | H32: 逾期利息
G33: =客户方案计算表!H6 -> 33970.463 | H33: 剩余本金
A37: 最小减免=合同金额-已还金额-核算后剩余本金-剩余法定利息 合同金额=每期还款*总期数 已还金额=每期还款*还款期数 剩余本金=实际到账金额-应付利息-冲销本金 应付利息=到账金额（剩余本金）*24%/12 剩余本金需要逐笔核减计算得出 剩余法定利息=剩余本金*17%/12*剩余期数 剩余本金需要逐笔核减计算得出
G38: =客户方案计算表!E4*45 -> 113790.6 | I38: 最小减免 | J38: =G38-G39-G40-G41-G43 -> 30325.629
G39: =客户方案计算表!E4*18 -> 45516.24
G40: =客户方案计算表!H6 -> 33970.463
G41: =客户方案计算表!H6*0.17/12 -> 481.24823
G43: 3497.02

Sheet Sheet1
F3: 借款金额 | G3: 分期期数 | H3: 每期还款金额 | I3: 已还期数 | J3: 最后一笔还款时间 | K3: 逾期期数
F4: 150000 | G4: 36 | H4: 6108 | I4: 11 | J4: 44063 | K4: 5
F5: 100000 | G5: 36 | H5: 4864 | I5: 19 | J5: 44520 | K5: 1
