Workbook

Sheet 客户方案计算表
B1: 2020.8.19日及之前的利率核算表 | H1: 2020.8.20日及之后的利率核算表
A2: 使用说明 | B2: 手动填写第一行数据 | C2: 还款期数为2020.8.19日及之前期数 此列需要手动填写 | D2: 计息本金*24%/12 此列为公式,不要修改 | E2: 与签订合同保持一致 此列第一格需要手动填写 | F2: 此列为公式 不要修改 | H2: 手动填写第一行数据 | I2: 还款期数为2020.8.20日及之后的期数 此列需要手动填写 | J2: 计息本金*17%/12 此列为公式,不要修改 | K2: 与签订合同保持一致 此列第一格需要手动填写 | L2: 此列为公式 不要修改
B3: 计息本金 | C3: 还款期数 （合同） | D3: 每月应还利息金额 | E3: 每月还款金额 | F3: 每月应抵本金 | H3: 计息本金 | I3: 还款期数 （合同） | J3: 每月应还利息金额 | K3: 每月还款金额 | L3: 每月应抵本金 | N3: 数值对应关系 | O3: 解释
B4: 150000 | C4: 1 | D4: =B4*24%/12 -> 3000 | E4: 6450 | F4: =E4-D4 -> 3450 | G4: 8.2 | H4: =B30 -> 33835.375 | I4: 27 | J4: =H4*17%/12 -> 479.33448 | K4: =E4 -> 6450 | L4: =K4-J4 -> 5970.6655 | N4: 计息本金=客户实际到账本金，不包含砍头息
B5: =B4-F4 -> 146550 | C5: 2 | D5: =B5*24%/12 -> 2931 | E5: =$E$4 -> 6450 | F5: =E5-D5 -> 3519 | G5: 9.2 | H5: =H4-L4 -> 27864.71 | I5: 28 | J5: =H5*17%/12 -> 394.75005 | K5: =$E$4 -> 6450 | L5: =K5-J5 -> 6055.2499 | N5: 每月应还利息=计息本金*17%/12 | O5: 每个月客户按17%应该还的利息
B6: =B5-F5 -> 143031 | C6: 3 | D6: =B6*24%/12 -> 2860.62 | E6: =$E$4 -> 6450 | F6: =E6-D6 -> 3589.38 | G6: 10.2 | H6: =H5-L5 -> 21809.46 | I6: 29 | J6: =H6*17%/12 -> 308.96735 | K6: =$E$4 -> 6450 | L6: =K6-J6 -> 6141.0327 | N6: 每月还款金额=合同约定还款金额
B7: =B6-F6 -> 139441.62 | C7: 4 | D7: =B7*24%/12 -> 2788.8324 | E7: =$E$4 -> 6450 | F7: =E7-D7 -> 3661.1676 | G7: 11.2 | H7: =H6-L6 -> 15668.427 | I7: 30 | J7: =H7*17%/12 -> 221.96938 | K7: =$E$4 -> 6450 | L7: =K7-J7 -> 6228.0306 | N7: 每月应抵本金=还款金额-应还利息金额
B8: =B7-F7 -> 135780.45 | C8: 5 | D8: =B8*24%/12 -> 2715.609 | E8: =$E$4 -> 6450 | F8: =E8-D8 -> 3734.391 | G8: 12.2 | H8: =H7-L7 -> 9440.3965 | I8: 31 | J8: =H8*17%/12 -> 133.73895 | K8: =$E$4 -> 6450 | L8: =K8-J8 -> 6316.261 | N8: 第二期计息本金=客户实际到账本金-应抵本金
B9: =B8-F8 -> 132046.06 | C9: 6 | D9: =B9*24%/12 -> 2640.9212 | E9: =$E$4 -> 6450 | F9: =E9-D9 -> 3809.0788 | G9: 1.2 | H9: =H8-L8 -> 3124.1355 | I9: 32 | J9: =H9*17%/12 -> 44.258586 | K9: =$E$4 -> 6450 | L9: =K9-J9 -> 6405.7414 | N9: 逾期利息=剩余本金*17%/12*逾期期数 | O9: 这个利息直到客户清偿之日为止
B10: =B9-F9 -> 128236.98 | C10: 7 | D10: =B10*24%/12 -> 2564.7397 | E10: =$E$4 -> 6450 | F10: =E10-D10 -> 3885.2603 | H10: =H9-L9 -> -3281.6059 | I10: 33 | J10: =H10*17%/12 -> -46.489417 | K10: =$E$4 -> 6450 | L10: =K10-J10 -> 6496.4894 | N10: 客户年化率，按鲸算师APP进行计算，进入APP后选择贷款利率
B11: =B10-F10 -> 124351.72 | C11: 8 | D11: =B11*24%/12 -> 2487.0344 | E11: =$E$4 -> 6450 | F11: =E11-D11 -> 3962.9656 | H11: =H10-L10 -> -9778.0953 | I11: 34 | J11: =H11*17%/12 -> -138.52302 | K11: =$E$4 -> 6450 | L11: =K11-J11 -> 6588.523 | N11: 借款总额 | O11: 客户实际到账金额
B12: =B11-F11 -> 120388.76 | C12: 9 | D12: =B12*24%/12 -> 2407.7751 | E12: =$E$4 -> 6450 | F12: =E12-D12 -> 4042.2249 | H12: =H11-L11 -> -16366.618 | I12: 35 | J12: =H12*17%/12 -> -231.86043 | K12: =$E$4 -> 6450 | L12: =K12-J12 -> 6681.8604
B13: =B12-F12 -> 116346.53 | C13: 10 | D13: =B13*24%/12 -> 2326.9306 | E13: =$E$4 -> 6450 | F13: =E13-D13 -> 4123.0694 | H13: =H12-L12 -> -23048.479 | I13: 36 | J13: =H13*17%/12 -> -326.52012 | K13: =$E$4 -> 6450 | L13: =K13-J13 -> 6776.5201 | N13: 在进行计算时，需要了解客户合同签订时间、还款期数。从签订合同之日起至2020.8.20日，每期年化率按24%核算，2020.8.20日至还款结清月份，每期年化率按17%核算。 表格一测算的是从客户签订合同之日起至2020.8.20日，每期年化率按24%核算的结果；表格二测算的是客户从2020.8.20日至还款结清月份，每期年化率按17%核算的结果
B14: =B13-F13 -> 112223.46 | C14: 11 | D14: =B14*24%/12 -> 2244.4693 | E14: =$E$4 -> 6450 | F14: =E14-D14 -> 4205.5307
B15: =B14-F14 -> 108017.93 | C15: 12 | D15: =B15*24%/12 -> 2160.3586 | E15: =$E$4 -> 6450 | F15: =E15-D15 -> 4289.6414
B16: =B15-F15 -> 103728.29 | C16: 13 | D16: =B16*24%/12 -> 2074.5658 | E16: =$E$4 -> 6450 | F16: =E16-D16 -> 4375.4342
B17: =B16-F16 -> 99352.856 | C17: 14 | D17: =B17*24%/12 -> 1987.0571 | E17: =$E$4 -> 6450 | F17: =E17-D17 -> 4462.9429
B18: =B17-F17 -> 94889.913 | C18: 15 | D18: =B18*24%/12 -> 1897.7983 | E18: =$E$4 -> 6450 | F18: =E18-D18 -> 4552.2017
B19: =B18-F18 -> 90337.712 | C19: 16 | D19: =B19*24%/12 -> 1806.7542 | E19: =$E$4 -> 6450 | F19: =E19-D19 -> 4643.2458
B20: =B19-F19 -> 85694.466 | C20: 17 | D20: =B20*24%/12 -> 1713.8893 | E20: =$E$4 -> 6450 | F20: =E20-D20 -> 4736.1107
B21: =B20-F20 -> 80958.355 | C21: 18 | D21: =B21*24%/12 -> 1619.1671 | E21: =$E$4 -> 6450 | F21: =E21-D21 -> 4830.8329
B22: =B21-F21 -> 76127.522 | C22: 19 | D22: =B22*24%/12 -> 1522.5504 | E22: =$E$4 -> 6450 | F22: =E22-D22 -> 4927.4496
B23: =B22-F22 -> 71200.073 | C23: 20 | D23: =B23*24%/12 -> 1424.0015 | E23: =$E$4 -> 6450 | F23: =E23-D23 -> 5025.9985
B24: =B23-F23 -> 66174.074 | C24: 21 | D24: =B24*24%/12 -> 1323.4815 | E24: =$E$4 -> 6450 | F24: =E24-D24 -> 5126.5185
B25: =B24-F24 -> 61047.556 | C25: 22 | D25: =B25*24%/12 -> 1220.9511 | E25: =$E$4 -> 6450 | F25: =E25-D25 -> 5229.0489
B26: =B25-F25 -> 55818.507 | C26: 23 | D26: =B26*24%/12 -> 1116.3701 | E26: =$E$4 -> 6450 | F26: =E26-D26 -> 5333.6299 | O26: 51535
B27: =B26-F26 -> 50484.877 | C27: 24 | D27: =B27*24%/12 -> 1009.6975 | E27: =$E$4 -> 6450 | F27: =E27-D27 -> 5440.3025 | O27: 1538.7
B28: =B27-F27 -> 45044.574 | C28: 25 | D28: =B28*24%/12 -> 900.89149 | E28: =$E$4 -> 6450 | F28: =E28-D28 -> 5549.1085 | O28: =O26+O27 -> 53073.7
A29: 7.2 | B29: =B28-F28 -> 39495.466 | C29: 26 | D29: =B29*24%/12 -> 789.90932 | E29: =$E$4 -> 6450 | F29: =E29-D29 -> 5660.0907
A30: 8.2 | B30: =B29-F29 -> 33835.375 | C30: 27 | D30: =B30*24%/12 -> 676.70751 | E30: =$E$4 -> 6450 | F30: =E30-D30 -> 5773.2925 | N30: =SUM(D4:D29) -> 51535.375
A31: 9.2 | B31: =B30-F30 -> 28062.083 | C31: 28 | D31: =B31*24%/12 -> 561.24166 | E31: =$E$4 -> 6450 | F31: =E31-D31 -> 5888.7583 | N31: =SUM(J4:J9) -> 1583.0188
A32: 10.2 | B32: =B31-F31 -> 22173.324 | C32: 29 | D32: =B32*24%/12 -> 443.46649 | E32: =$E$4 -> 6450 | F32: =E32-D32 -> 6006.5335 | J32: =H32*17%/12 -> 0 | N32: =N30+N31 -> 53118.394
A33: 11.2 | B33: =B32-F32 -> 16166.791 | C33: 30 | D33: =B33*24%/12 -> 323.33582 | E33: =$E$4 -> 6450 | F33: =E33-D33 -> 6126.6642 | J33: =H33*17%/12 -> 0
B34: =B33-F33 -> 10040.127 | C34: 31 | D34: =B34*24%/12 -> 200.80253 | E34: =$E$4 -> 6450 | F34: =E34-D34 -> 6249.1975 | J34: =H34*17%/12 -> 0
B35: =B34-F34 -> 3790.9293 | C35: 32 | D35: =B35*24%/12 -> 75.818586 | E35: =$E$4 -> 6450 | F35: =E35-D35 -> 6374.1814 | J35: =H35*17%/12 -> 0
B36: =B35-F35 -> -2583.2521 | C36: 33 | D36: =B36*24%/12 -> -51.665043 | E36: =$E$4 -> 6450 | F36: =E36-D36 -> 6501.665 | J36: =H36*17%/12 -> 0
B37: =B36-F36 -> -9084.9172 | C37: 34 | D37: =B37*24%/12 -> -181.69834 | E37: =$E$4 -> 6450 | F37: =E37-D37 -> 6631.6983 | J37: =H37*17%/12 -> 0
B38: =B37-F37 -> -15716.616 | C38: 35 | D38: =B38*24%/12 -> -314.33231 | E38: =$E$4 -> 6450 | F38: =E38-D38 -> 6764.3323 | J38: =H38*17%/12 -> 0
B39: =B38-F38 -> -22480.948 | C39: 36 | D39: =B39*24%/12 -> -449.61896 | E39: =$E$4 -> 6450 | F39: =E39-D39 -> 6899.619 | J39: =H39*17%/12 -> 0
C41: 已付利息： | D41: =SUM(D4:D13)+J4 -> 27202.797 | E41: =SUM(E4:E14) -> 70950 | F41: =D41+J41 -> 26503.663 | I41: 未付利息： | J41: =SUM(J9:J21) -> -699.13439
...

Sheet 逾期利息
A1: 逾期利息=剩余本金*24%/12*逾期期数 | F1: 绿色为手工填写
A2: 逾期利息=剩余本金*17%/12*逾期期数
A3: 剩余本金 | B3: 利率 | C3: 12个月 | D3: 逾期期数 | E3: 逾期利息
A4: 176284.8 | B4: 0.24 | C4: 12 | D4: 0 | E4: =A4*B4/C4*D4 -> 0
A5: 111503.15 | B5: 0.17 | C5: 12 | D5: 5 | E5: =A5*B5/C5*D5 -> 7898.1398

Sheet 减免计算
B1: 合同金额 | C1: 实际到账 | D1: 分期总数 | E1: 每期金额 | F1: 2020.8.19及之前期数 | G1: 2020.8.20及之后期数 | H1: 已还期数 | I1: 未还期数 | J1: 逾期 | K1: 应付利息 | L1: 结果
A2: 减免最大值 | B2: =客户方案计算表!E4*36 -> 232200 | C2: =客户方案计算表!B4 -> 150000 | D2: 36 | E2: =客户方案计算表!E4 -> 6450 | F2: 10 | G2: 22 | H2: 11 | I2: 21 | J2: 4 | K2: =客户方案计算表!F41 -> 26503.663 | L2: =B2-C2-客户方案计算表!D41 -> 54997.203
G3: =D3-F3 -> 0 | I3: =D3-H3 -> 0
A4: 减免最小值 | B4: =客户方案计算表!E4*36 -> 232200 | C4: =客户方案计算表!B4 -> 150000 | D4: 36 | E4: =客户方案计算表!E4 -> 6450 | F4: 10 | G4: 22 | H4: 11 | I4: 21 | J4: 4 | K4: =客户方案计算表!F41 -> 26503.663 | L4: =B4-C4-客户方案计算表!D41-客户方案计算表!J41 -> 55696.337
A21: 计算逻辑： 最大减免=合同金额-到账金额-应付利息 合同金额=每期还款*总期数 应付利息=到账金额*24%*（合同签订日期至2020年8月20日的期数）+到账金额*17*（2020年8月20日至客户最后一次还款那个月的期数） 最小减免=合同金额-到账金额-应付利息 应付利息=到账金额*24%*（合同签订日期至2020年8月20日的期数）+到账金额*17*（36-（合同签订日期至2020年8月20日的期数））
A28: 最大减免=合同金额-已还金额-核算后剩余本金 合同金额=每期还款*总期数 已还金额=每期还款*还款期数 剩余本金=实际到账金额-应付利息-冲销本金 应付利息=到账金额（剩余本金）*24%/12 剩余本金需要逐笔核减计算得出
G30: =客户方案计算表!E4*36 -> 232200 | H30: =G30-G31-G32-G33 -> 29072.603
G31: =客户方案计算表!E4*30 -> 193500
G32: =客户方案计算表!H8 -> 9440.3965
G33: 187
A37: 最小减免=合同金额-已还金额-核算后剩余本金-剩余法定利息 合同金额=每期还款*总期数 已还金额=每期还款*还款期数 剩余本金=实际到账金额-应付利息-冲销本金 应付利息=到账金额（剩余本金）*24%/12 剩余本金需要逐笔核减计算得出 剩余法定利息=剩余本金*17%/12*剩余期数 剩余本金需要逐笔核减计算得出

Sheet Sheet1
F3: 借款金额 | G3: 分期期数 | H3: 每期还款金额 | I3: 已还期数 | J3: 最后一笔还款时间 | K3: 逾期期数
F4: 150000 | G4: 36 | H4: 6108 | I4: 11 | J4: 44063 | K4: 5
F5: 100000 | G5: 36 | H5: 4864 | I5: 19 | J5: 44520 | K5: 1
