Workbook

Sheet 客户方案计算表
B1: 2020.8.19日及之前的利率核算表 | H1: 2020.8.20日及之后的利率核算表
A2: 使用说明 | B2: 手动填写第一行数据 | C2: 还款期数为2020.8.19日及之前期数 此列需要手动填写 | D2: 计息本金*24%/12 此列为公式,不要修改 | E2: 与签订合同保持一致 此列第一格需要手动填写 | F2: 此列为公式 不要修改 | H2: 手动填写第一行数据 | I2: 还款期数为2020.8.20日及之后的期数 此列需要手动填写 | J2: 计息本金*17%/12 此列为公式,不要修改 | K2: 与签订合同保持一致 此列第一格需要手动填写 | L2: 此列为公式 不要修改
B3: 计息本金 | C3: 还款期数 （合同） | D3: 每月应还利息金额 | E3: 每月还款金额 | F3: 每月应抵本金 | H3: 计息本金 | I3: 还款期数 （合同） | J3: 每月应还利息金额 | K3: 每月还款金额 | L3: 每月应抵本金 | N3: 数值对应关系 | O3: 解释
B4: 180000 | C4: 1 | D4: =B4*24%/12 -> 3600 | E4: 8233.72 | F4: =E4-D4 -> 4633.72 | G4: 9.12 | H4: 160901.62 | I4: 5 | J4: =H4*17%/12 -> 2279.4396 | K4: =E4 -> 8233.72 | L4: =K4-J4 -> 5954.2804 | N4: 计息本金=客户实际到账本金，不包含砍头息
B5: =B4-F4 -> 175366.28 | C5: 2 | D5: =B5*24%/12 -> 3507.3256 | E5: =$E$4 -> 8233.72 | F5: =E5-D5 -> 4726.3944 | G5: 10.12 | H5: =H4-L4 -> 154947.34 | I5: 6 | J5: =H5*17%/12 -> 2195.0873 | K5: =$E$4 -> 8233.72 | L5: =K5-J5 -> 6038.6327 | N5: 每月应还利息=计息本金*17%/12 | O5: 每个月客户按17%应该还的利息
A6: 7.12 | B6: =B5-F5 -> 170639.89 | C6: 3 | D6: =B6*24%/12 -> 3412.7977 | E6: =$E$4 -> 8233.72 | F6: =E6-D6 -> 4820.9223 | G6: 11.12 | H6: =H5-L5 -> 148908.71 | I6: 7 | J6: =H6*17%/12 -> 2109.54 | K6: =$E$4 -> 8233.72 | L6: =K6-J6 -> 6124.18 | N6: 每月还款金额=合同约定还款金额
A7: 8.12 | B7: =B6-F6 -> 165818.96 | C7: 4 | D7: =B7*24%/12 -> 3316.3793 | E7: =$E$4 -> 8233.72 | F7: =E7-D7 -> 4917.3407 | G7: 12.12 | H7: =H6-L6 -> 142784.53 | I7: 8 | J7: =H7*17%/12 -> 2022.7808 | K7: =$E$4 -> 8233.72 | L7: =K7-J7 -> 6210.9392 | N7: 每月应抵本金=还款金额-应还利息金额
B8: =B7-F7 -> 160901.62 | C8: 5 | D8: =B8*24%/12 -> 3218.0325 | E8: =$E$4 -> 8233.72 | F8: =E8-D8 -> 5015.6875 | G8: 1.12 | H8: =H7-L7 -> 136573.59 | I8: 9 | J8: =H8*17%/12 -> 1934.7925 | K8: =$E$4 -> 8233.72 | L8: =K8-J8 -> 6298.9275 | N8: 第二期计息本金=客户实际到账本金-应抵本金
B9: =B8-F8 -> 155885.94 | C9: 6 | D9: =B9*24%/12 -> 3117.7187 | E9: =$E$4 -> 8233.72 | F9: =E9-D9 -> 5116.0013 | H9: =H8-L8 -> 130274.66 | I9: 10 | J9: =H9*17%/12 -> 1845.5577 | K9: =$E$4 -> 8233.72 | L9: =K9-J9 -> 6388.1623 | N9: 逾期利息=剩余本金*17%/12*逾期期数 | O9: 这个利息直到客户清偿之日为止
B10: =B9-F9 -> 150769.93 | C10: 7 | D10: =B10*24%/12 -> 3015.3987 | E10: =$E$4 -> 8233.72 | F10: =E10-D10 -> 5218.3213 | H10: =H9-L9 -> 123886.5 | I10: 11 | J10: =H10*17%/12 -> 1755.0587 | K10: =$E$4 -> 8233.72 | L10: =K10-J10 -> 6478.6613 | N10: 客户年化率，按鲸算师APP进行计算，进入APP后选择贷款利率
B11: =B10-F10 -> 145551.61 | C11: 8 | D11: =B11*24%/12 -> 2911.0322 | E11: =$E$4 -> 8233.72 | F11: =E11-D11 -> 5322.6878 | H11: =H10-L10 -> 117407.84 | I11: 12 | J11: =H11*17%/12 -> 1663.2777 | K11: =$E$4 -> 8233.72 | L11: =K11-J11 -> 6570.4423 | N11: 借款总额 | O11: 客户实际到账金额
B12: =B11-F11 -> 140228.92 | C12: 9 | D12: =B12*24%/12 -> 2804.5785 | E12: =$E$4 -> 8233.72 | F12: =E12-D12 -> 5429.1415 | H12: =H11-L11 -> 110837.39 | I12: 13 | J12: =H12*17%/12 -> 1570.1964 | K12: =$E$4 -> 8233.72 | L12: =K12-J12 -> 6663.5236
B13: =B12-F12 -> 134799.78 | C13: 10 | D13: =B13*24%/12 -> 2695.9957 | E13: =$E$4 -> 8233.72 | F13: =E13-D13 -> 5537.7243 | H13: =H12-L12 -> 104173.87 | I13: 14 | J13: =H13*17%/12 -> 1475.7965 | K13: =$E$4 -> 8233.72 | L13: =K13-J13 -> 6757.9235 | N13: 在进行计算时，需要了解客户合同签订时间、还款期数。从签订合同之日起至2020.8.20日，每期年化率按24%核算，2020.8.20日至还款结清月份，每期年化率按17%核算。 表格一测算的是从客户签订合同之日起至2020.8.20日，每期年化率按24%核算的结果；表格二测算的是客户从2020.8.20日至还款结清月份，每期年化率按17%核算的结果
B14: =B13-F13 -> 129262.06 | C14: 11 | D14: =B14*24%/12 -> 2585.2412 | E14: =$E$4 -> 8233.72 | F14: =E14-D14 -> 5648.4788 | H14: =H13-L13 -> 97415.947 | I14: 15 | J14: =H14*17%/12 -> 1380.0593 | K14: =$E$4 -> 8233.72 | L14: =K14-J14 -> 6853.6607
B15: =B14-F14 -> 123613.58 | C15: 12 | D15: =B15*24%/12 -> 2472.2716 | E15: =$E$4 -> 8233.72 | F15: =E15-D15 -> 5761.4484 | H15: =H14-L14 -> 90562.287 | I15: 16 | J15: =H15*17%/12 -> 1282.9657 | K15: =$E$4 -> 8233.72 | L15: =K15-J15 -> 6950.7543
B16: =B15-F15 -> 117852.13 | C16: 13 | D16: =B16*24%/12 -> 2357.0426 | E16: =$E$4 -> 8233.72 | F16: =E16-D16 -> 5876.6774 | H16: =H15-L15 -> 83611.532 | I16: 17 | J16: =H16*17%/12 -> 1184.4967 | K16: =$E$4 -> 8233.72 | L16: =K16-J16 -> 7049.2233
B17: =B16-F16 -> 111975.45 | C17: 14 | D17: =B17*24%/12 -> 2239.5091 | E17: =$E$4 -> 8233.72 | F17: =E17-D17 -> 5994.2109 | H17: =H16-L16 -> 76562.309 | I17: 18 | J17: =H17*17%/12 -> 1084.6327 | K17: =$E$4 -> 8233.72 | L17: =K17-J17 -> 7149.0873
B18: =B17-F17 -> 105981.24 | C18: 15 | D18: =B18*24%/12 -> 2119.6249 | E18: =$E$4 -> 8233.72 | F18: =E18-D18 -> 6114.0951 | H18: =H17-L17 -> 69413.222 | I18: 19 | J18: =H18*17%/12 -> 983.35397 | K18: =$E$4 -> 8233.72 | L18: =K18-J18 -> 7250.366
B19: =B18-F18 -> 99867.148 | C19: 16 | D19: =B19*24%/12 -> 1997.343 | E19: =$E$4 -> 8233.72 | F19: =E19-D19 -> 6236.377 | H19: =H18-L18 -> 62162.856 | I19: 20 | J19: =H19*17%/12 -> 880.64045 | K19: =$E$4 -> 8233.72 | L19: =K19-J19 -> 7353.0795
B20: =B19-F19 -> 93630.771 | C20: 17 | D20: =B20*24%/12 -> 1872.6154 | E20: =$E$4 -> 8233.72 | F20: =E20-D20 -> 6361.1046 | H20: =H19-L19 -> 54809.776 | I20: 21 | J20: =H20*17%/12 -> 776.47183 | K20: =$E$4 -> 8233.72 | L20: =K20-J20 -> 7457.2482
B21: =B20-F20 -> 87269.667 | C21: 18 | D21: =B21*24%/12 -> 1745.3933 | E21: =$E$4 -> 8233.72 | F21: =E21-D21 -> 6488.3267 | H21: =H20-L20 -> 47352.528 | I21: 22 | J21: =H21*17%/12 -> 670.82748 | K21: =$E$4 -> 8233.72 | L21: =K21-J21 -> 7562.8925
B22: =B21-F21 -> 80781.34 | C22: 19 | D22: =B22*24%/12 -> 1615.6268 | E22: =$E$4 -> 8233.72 | F22: =E22-D22 -> 6618.0932 | H22: =H21-L21 -> 39789.635 | I22: 23 | J22: =H22*17%/12 -> 563.6865 | K22: =$E$4 -> 8233.72 | L22: =K22-J22 -> 7670.0335
B23: =B22-F22 -> 74163.247 | C23: 20 | D23: =B23*24%/12 -> 1483.2649 | E23: =$E$4 -> 8233.72 | F23: =E23-D23 -> 6750.4551 | H23: =H22-L22 -> 32119.602 | I23: 24 | J23: =H23*17%/12 -> 455.02769 | K23: =$E$4 -> 8233.72 | L23: =K23-J23 -> 7778.6923
B24: =B23-F23 -> 67412.792 | C24: 21 | D24: =B24*24%/12 -> 1348.2558 | E24: =$E$4 -> 8233.72 | F24: =E24-D24 -> 6885.4642 | H24: =H23-L23 -> 24340.91 | I24: 25 | J24: =H24*17%/12 -> 344.82955 | K24: =$E$4 -> 8233.72 | L24: =K24-J24 -> 7888.8904
B25: =B24-F24 -> 60527.327 | C25: 22 | D25: =B25*24%/12 -> 1210.5465 | E25: =$E$4 -> 8233.72 | F25: =E25-D25 -> 7023.1735 | H25: =H24-L24 -> 16452.019 | I25: 26 | J25: =H25*17%/12 -> 233.07027 | K25: =$E$4 -> 8233.72 | L25: =K25-J25 -> 8000.6497
... B35: =B34-F34 -> -16374.462 | C35: 32 | D35: =B35*24%/12 -> -327.48925 | E35: =$E$4 -> 8233.72 | F35: =E35-D35 -> 8561.2092 | H35: =H34-L34 -> -68852.434 | I35: 36 | J35: =H35*17%/12 -> -975.40948 | K35: =$E$4 -> 8233.72 | L35: =K35-J35 -> 9209.1295
B36: =B35-F35 -> -24935.672 | C36: 33 | D36: =B36*24%/12 -> -498.71343 | E36: =$E$4 -> 8233.72 | F36: =E36-D36 -> 8732.4334 | J36: =H36*17%/12 -> 0
B37: =B36-F36 -> -33668.105 | C37: 34 | D37: =B37*24%/12 -> -673.3621 | E37: =$E$4 -> 8233.72 | F37: =E37-D37 -> 8907.0821 | J37: =H37*17%/12 -> 0
B38: =B37-F37 -> -42575.187 | C38: 35 | D38: =B38*24%/12 -> -851.50374 | E38: =$E$4 -> 8233.72 | F38: =E38-D38 -> 9085.2237 | J38: =H38*17%/12 -> 0
B39: =B38-F38 -> -51660.411 | C39: 36 | D39: =B39*24%/12 -> -1033.2082 | E39: =$E$4 -> 8233.72 | F39: =E39-D39 -> 9266.9282 | J39: =H39*17%/12 -> 0
C41: 已付利息： | D41: =SUM(D4:D7)+SUM(J4:J8) -> 24378.143 | E41: =SUM(E4:E14) -> 90570.92 | F41: =D41+J41 -> 40931.478 | I41: 未付利息： | J41: =SUM(J9:J21) -> 16553.335
I42: 逾期利息 | J42: =SUM(J5:J8) -> 8262.2006
E43: =E4*36 -> 296413.92 | F43: =B4 -> 180000
F45: =E43-D41-B4-J42 -> 83773.577 | H45: 最大减免=合同总金额-本金-已还利息-逾期利息
F47: =E43-B4-D41-J41-J42 -> 67220.241 | H47: 最小减免=合同总金额-本金-全部法定利息-逾期利息
C49: 合同金额 | D49: =E4*C39 -> 296413.92
C50: 本金 | D50: =B4 -> 180000 | G50: 客户情况：本金180000 最后一次还款1.12 每月还款金额8233.72 已还9期 逾期0 已还金额74103.48
C51: 已还利息 | D51: =SUM(D4:D7)+SUM(J4:J8) -> 24378.143
C52: 逾期利息 | D52: 0 | E52: 逾期4期
C53: 全部法定利息 | D53: =SUM(D4:D7)+SUM(J4:J27) -> 42652.599 | E53: j28 j29 负数不算
...

Sheet 逾期利息
A1: 逾期利息=剩余本金*24%/12*逾期期数 | F1: 绿色为手工填写
A2: 逾期利息=剩余本金*17%/12*逾期期数
A3: 剩余本金 | B3: 利率 | C3: 12个月 | D3: 逾期期数 | E3: 逾期利息
A4: 176284.8 | B4: 0.24 | C4: 12 | D4: 0 | E4: =A4*B4/C4*D4 -> 0
A5: 111503.15 | B5: 0.17 | C5: 12 | D5: 5 | E5: =A5*B5/C5*D5 -> 7898.1398

Sheet 减免计算
B1: 合同金额 | C1: 实际到账 | D1: 分期总数 | E1: 每期金额 | F1: 2020.8.19及之前期数 | G1: 2020.8.20及之后期数 | H1: 已还期数 | I1: 未还期数 | J1: 逾期 | K1: 应付利息 | L1: 结果
A2: 减免最大值 | B2: =客户方案计算表!E4*36 -> 296413.92 | C2: =客户方案计算表!B4 -> 180000 | D2: 36 | E2: =客户方案计算表!E4 -> 8233.72 | F2: 10 | G2: 22 | H2: 11 | I2: 21 | J2: 4 | K2: =客户方案计算表!F41 -> 40931.478 | L2: =B2-C2-客户方案计算表!D41 -> 92035.777
G3: =D3-F3 -> 0 | I3: =D3-H3 -> 0
A4: 减免最小值 | B4: =客户方案计算表!E4*36 -> 296413.92 | C4: =客户方案计算表!B4 -> 180000 | D4: 36 | E4: =客户方案计算表!E4 -> 8233.72 | F4: 10 | G4: 22 | H4: 11 | I4: 21 | J4: 4 | K4: =客户方案计算表!F41 -> 40931.478 | L4: =B4-C4-客户方案计算表!D41-客户方案计算表!J41 -> 75482.442
A6: 计算逻辑： 最大减免=合同金额-到账金额-应付利息 合同金额=每期还款*总期数 应付利息=到账金额*24%*（合同签订日期至2020年8月20日的期数）+到账金额*17*（2020年8月20日至客户最后一次还款那个月的期数） 最小减免=合同金额-到账金额-应付利息 应付利息=到账金额*24%*（合同签订日期至2020年8月20日的期数）+到账金额*17*（36-（合同签订日期至2020年8月20日的期数））
A13: 最大减免=合同金额-已还金额-核算后剩余本金 合同金额=每期还款*总期数 已还金额=每期还款*还款期数 剩余本金=实际到账金额-应付利息-冲销本金 应付利息=到账金额（剩余本金）*24%/12 剩余本金需要逐笔核减计算得出
A22: 最小减免=合同金额-已还金额-核算后剩余本金-剩余法定利息 合同金额=每期还款*总期数 已还金额=每期还款*还款期数 剩余本金=实际到账金额-应付利息-冲销本金 应付利息=到账金额（剩余本金）*24%/12 剩余本金需要逐笔核减计算得出 剩余法定利息=剩余本金*17%/12*剩余期数 剩余本金需要逐笔核减计算得出

Sheet Sheet1
F3: 借款金额 | G3: 分期期数 | H3: 每期还款金额 | I3: 已还期数 | J3: 最后一笔还款时间 | K3: 逾期期数
F4: 150000 | G4: 36 | H4: 6108 | I4: 11 | J4: 44063 | K4: 5
F5: 100000 | G5: 36 | H5: 4864 | I5: 19 | J5: 44520 | K5: 1
