Workbook

Sheet 客户方案计算表
B1: 2020.8.19日及之前的利率核算表 | H1: 2020.8.20日及之后的利率核算表
A2: 使用说明 | B2: 手动填写第一行数据 | C2: 还款期数为2020.8.19日及之前期数 此列需要手动填写 | D2: 计息本金*24%/12 此列为公式,不要修改 | E2: 与签订合同保持一致 此列第一格需要手动填写 | F2: 此列为公式 不要修改 | H2: 手动填写第一行数据 | I2: 还款期数为2020.8.20日及之后的期数 此列需要手动填写 | J2: 计息本金*17%/12 此列为公式,不要修改 | K2: 与签订合同保持一致 此列第一格需要手动填写 | L2: 此列为公式 不要修改
B3: 计息本金 | C3: 还款期数 （合同） | D3: 每月应还利息金额 | E3: 每月还款金额 | F3: 每月应抵本金 | H3: 计息本金 | I3: 还款期数 （合同） | J3: 每月应还利息金额 | K3: 每月还款金额 | L3: 每月应抵本金 | N3: 数值对应关系 | O3: 解释
B4: 150000 | C4: 1 | D4: =B4*24%/12 -> 3000 | E4: 6108.08 | F4: =E4-D4 -> 3108.08 | H4: 115967.39 | I4: 11 | J4: =H4*17%/12 -> 1642.8714 | K4: 6108.08 | L4: =K4-J4 -> 4465.2086 | N4: 计息本金=客户实际到账本金，不包含砍头息
B5: =B4-F4 -> 146891.92 | C5: 2 | D5: =B5*24%/12 -> 2937.8384 | E5: =$E$4 -> 6108.08 | F5: =E5-D5 -> 3170.2416 | H5: =H4-L4 -> 111502.18 | I5: 12 | J5: =H5*17%/12 -> 1579.6143 | K5: =$E$4 -> 6108.08 | L5: =K5-J5 -> 4528.4657 | N5: 每月应还利息=计息本金*17%/12 | O5: 每个月客户按17%应该还的利息
B6: =B5-F5 -> 143721.68 | C6: 3 | D6: =B6*24%/12 -> 2874.4336 | E6: =$E$4 -> 6108.08 | F6: =E6-D6 -> 3233.6464 | H6: =H5-L5 -> 106973.72 | I6: 13 | J6: =H6*17%/12 -> 1515.461 | K6: =$E$4 -> 6108.08 | L6: =K6-J6 -> 4592.619 | N6: 每月还款金额=合同约定还款金额
B7: =B6-F6 -> 140488.03 | C7: 4 | D7: =B7*24%/12 -> 2809.7606 | E7: =$E$4 -> 6108.08 | F7: =E7-D7 -> 3298.3194 | H7: =H6-L6 -> 102381.1 | I7: 14 | J7: =H7*17%/12 -> 1450.3989 | K7: =$E$4 -> 6108.08 | L7: =K7-J7 -> 4657.6811 | N7: 每月应抵本金=还款金额-应还利息金额
B8: =B7-F7 -> 137189.71 | C8: 5 | D8: =B8*24%/12 -> 2743.7943 | E8: =$E$4 -> 6108.08 | F8: =E8-D8 -> 3364.2857 | H8: =H7-L7 -> 97723.417 | I8: 15 | J8: =H8*17%/12 -> 1384.4151 | K8: =$E$4 -> 6108.08 | L8: =K8-J8 -> 4723.6649 | N8: 第二期计息本金=客户实际到账本金-应抵本金
B9: =B8-F8 -> 133825.43 | C9: 6 | D9: =B9*24%/12 -> 2676.5085 | E9: =$E$4 -> 6108.08 | F9: =E9-D9 -> 3431.5715 | H9: =H8-L8 -> 92999.752 | I9: 16 | J9: =H9*17%/12 -> 1317.4965 | K9: =$E$4 -> 6108.08 | L9: =K9-J9 -> 4790.5835 | N9: 逾期利息=剩余本金*17%/12*逾期期数 | O9: 这个利息直到客户清偿之日为止
B10: =B9-F9 -> 130393.86 | C10: 7 | D10: =B10*24%/12 -> 2607.8771 | E10: =$E$4 -> 6108.08 | F10: =E10-D10 -> 3500.2029 | H10: =H9-L9 -> 88209.168 | I10: 17 | J10: =H10*17%/12 -> 1249.6299 | K10: =$E$4 -> 6108.08 | L10: =K10-J10 -> 4858.4501 | N10: 客户年化率，按鲸算师APP进行计算，进入APP后选择贷款利率
B11: =B10-F10 -> 126893.65 | C11: 8 | D11: =B11*24%/12 -> 2537.8731 | E11: =$E$4 -> 6108.08 | F11: =E11-D11 -> 3570.2069 | H11: =H10-L10 -> 83350.718 | I11: 18 | J11: =H11*17%/12 -> 1180.8018 | K11: =$E$4 -> 6108.08 | L11: =K11-J11 -> 4927.2782 | N11: 借款总额 | O11: 客户实际到账金额
B12: =B11-F11 -> 123323.45 | C12: 9 | D12: =B12*24%/12 -> 2466.4689 | E12: =$E$4 -> 6108.08 | F12: =E12-D12 -> 3641.6111 | H12: =H11-L11 -> 78423.44 | I12: 19 | J12: =H12*17%/12 -> 1110.9987 | K12: =$E$4 -> 6108.08 | L12: =K12-J12 -> 4997.0813
B13: =B12-F12 -> 119681.83 | C13: 10 | D13: =B13*24%/12 -> 2393.6367 | E13: =$E$4 -> 6108.08 | F13: =E13-D13 -> 3714.4433 | H13: =H12-L12 -> 73426.359 | I13: 20 | J13: =H13*17%/12 -> 1040.2067 | K13: =$E$4 -> 6108.08 | L13: =K13-J13 -> 5067.8733 | N13: 在进行计算时，需要了解客户合同签订时间、还款期数。从签订合同之日起至2020.8.20日，每期年化率按24%核算，2020.8.20日至还款结清月份，每期年化率按17%核算。 表格一测算的是从客户签订合同之日起至2020.8.20日，每期年化率按24%核算的结果；表格二测算的是客户从2020.8.20日至还款结清月份，每期年化率按17%核算的结果
B14: =B13-F13 -> 115967.39 | C14: 11 | D14: =B14*24%/12 -> 2319.3478 | E14: =$E$4 -> 6108.08 | F14: =E14-D14 -> 3788.7322 | H14: =H13-L13 -> 68358.485 | I14: 21 | J14: =H14*17%/12 -> 968.41188 | K14: =$E$4 -> 6108.08 | L14: =K14-J14 -> 5139.6681
D15: =B15*24%/12 -> 0 | E15: =$E$4 -> 6108.08 | F15: =E15-D15 -> 6108.08 | H15: =H14-L14 -> 63218.817 | I15: 22 | J15: =H15*17%/12 -> 895.59991 | K15: =$E$4 -> 6108.08 | L15: =K15-J15 -> 5212.4801
D16: =B16*24%/12 -> 0 | E16: =$E$4 -> 6108.08 | F16: =E16-D16 -> 6108.08 | H16: =H15-L15 -> 58006.337 | I16: 23 | J16: =H16*17%/12 -> 821.75644 | K16: =$E$4 -> 6108.08 | L16: =K16-J16 -> 5286.3236
D17: =B17*24%/12 -> 0 | E17: =$E$4 -> 6108.08 | F17: =E17-D17 -> 6108.08 | H17: =H16-L16 -> 52720.014 | I17: 24 | J17: =H17*17%/12 -> 746.86686 | K17: =$E$4 -> 6108.08 | L17: =K17-J17 -> 5361.2131
D18: =B18*24%/12 -> 0 | E18: =$E$4 -> 6108.08 | F18: =E18-D18 -> 6108.08 | H18: =H17-L17 -> 47358.801 | I18: 25 | J18: =H18*17%/12 -> 670.91634 | K18: =$E$4 -> 6108.08 | L18: =K18-J18 -> 5437.1637
D19: =B19*24%/12 -> 0 | E19: =$E$4 -> 6108.08 | F19: =E19-D19 -> 6108.08 | H19: =H18-L18 -> 41921.637 | I19: 26 | J19: =H19*17%/12 -> 593.88986 | K19: =$E$4 -> 6108.08 | L19: =K19-J19 -> 5514.1901
D20: =B20*24%/12 -> 0 | E20: =$E$4 -> 6108.08 | F20: =E20-D20 -> 6108.08 | H20: =H19-L19 -> 36407.447 | I20: 27 | J20: =H20*17%/12 -> 515.77216 | K20: =$E$4 -> 6108.08 | L20: =K20-J20 -> 5592.3078
D21: =B21*24%/12 -> 0 | E21: =$E$4 -> 6108.08 | F21: =E21-D21 -> 6108.08 | H21: =H20-L20 -> 30815.139 | I21: 28 | J21: =H21*17%/12 -> 436.5478 | K21: =$E$4 -> 6108.08 | L21: =K21-J21 -> 5671.5322
D22: =B22*24%/12 -> 0 | E22: =$E$4 -> 6108.08 | F22: =E22-D22 -> 6108.08 | H22: =H21-L21 -> 25143.607 | I22: 29 | J22: =H22*17%/12 -> 356.20109 | K22: =$E$4 -> 6108.08 | L22: =K22-J22 -> 5751.8789
D23: =B23*24%/12 -> 0 | E23: =$E$4 -> 6108.08 | F23: =E23-D23 -> 6108.08 | H23: =H22-L22 -> 19391.728 | I23: 30 | J23: =H23*17%/12 -> 274.71614 | K23: =$E$4 -> 6108.08 | L23: =K23-J23 -> 5833.3639
D24: =B24*24%/12 -> 0 | E24: =$E$4 -> 6108.08 | F24: =E24-D24 -> 6108.08 | H24: =H23-L23 -> 13558.364 | I24: 31 | J24: =H24*17%/12 -> 192.07682 | K24: =$E$4 -> 6108.08 | L24: =K24-J24 -> 5916.0032 | N24: =36-10 -> 26
D25: =B25*24%/12 -> 0 | E25: =$E$4 -> 6108.08 | F25: =E25-D25 -> 6108.08 | H25: =H24-L24 -> 7642.3607 | I25: 32 | J25: =H25*17%/12 -> 108.26678 | K25: =$E$4 -> 6108.08 | L25: =K25-J25 -> 5999.8132
D26: =B26*24%/12 -> 0 | E26: =$E$4 -> 6108.08 | F26: =E26-D26 -> 6108.08 | H26: =H25-L25 -> 1642.5475 | I26: 33 | J26: =H26*17%/12 -> 23.269423 | K26: =$E$4 -> 6108.08 | L26: =K26-J26 -> 6084.8106
D27: =B27*24%/12 -> 0 | E27: =$E$4 -> 6108.08 | F27: =E27-D27 -> 6108.08 | H27: =H26-L26 -> -4442.2631 | I27: 34 | J27: =H27*17%/12 -> -62.93206 | K27: =$E$4 -> 6108.08 | L27: =K27-J27 -> 6171.0121
D28: =B28*24%/12 -> 0 | E28: =$E$4 -> 6108.08 | F28: =E28-D28 -> 6108.08 | H28: =H27-L27 -> -10613.275 | I28: 35 | J28: =H28*17%/12 -> -150.35473 | K28: =$E$4 -> 6108.08 | L28: =K28-J28 -> 6258.4347
D29: =B29*24%/12 -> 0 | E29: =$E$4 -> 6108.08 | F29: =E29-D29 -> 6108.08 | H29: =H28-L28 -> -16871.71 | I29: 36 | J29: =H29*17%/12 -> -239.01589 | K29: =$E$4 -> 6108.08 | L29: =K29-J29 -> 6347.0959
D30: =B30*24%/12 -> 0 | E30: =$E$4 -> 6108.08 | F30: =E30-D30 -> 6108.08 | J30: =H30*17%/12 -> 0
D31: =B31*24%/12 -> 0 | E31: =$E$4 -> 6108.08 | F31: =E31-D31 -> 6108.08 | J31: =H31*17%/12 -> 0
D32: =B32*24%/12 -> 0 | E32: =$E$4 -> 6108.08 | F32: =E32-D32 -> 6108.08 | J32: =H32*17%/12 -> 0
D33: =B33*24%/12 -> 0 | E33: =$E$4 -> 6108.08 | F33: =E33-D33 -> 6108.08 | J33: =H33*17%/12 -> 0
D34: =B34*24%/12 -> 0 | E34: =$E$4 -> 6108.08 | F34: =E34-D34 -> 6108.08 | J34: =H34*17%/12 -> 0
D35: =B35*24%/12 -> 0 | E35: =$E$4 -> 6108.08 | F35: =E35-D35 -> 6108.08 | J35: =H35*17%/12 -> 0
D36: =B36*24%/12 -> 0 | E36: =$E$4 -> 6108.08 | F36: =E36-D36 -> 6108.08 | J36: =H36*17%/12 -> 0
D37: =B37*24%/12 -> 0 | E37: =$E$4 -> 6108.08 | F37: =E37-D37 -> 6108.08 | J37: =H37*17%/12 -> 0
D38: =B38*24%/12 -> 0 | E38: =$E$4 -> 6108.08 | F38: =E38-D38 -> 6108.08 | J38: =H38*17%/12 -> 0
D39: =B39*24%/12 -> 0 | E39: =$E$4 -> 6108.08 | F39: =E39-D39 -> 6108.08 | J39: =H39*17%/12 -> 0
C41: 应付利息： | D41: =SUM(D4:D13) -> 27048.191 | E41: =SUM(E4:E13) -> 61080.8 | I41: 应付利息： | J41: =SUM(J4:J26) -> 20076.186
...

Sheet 逾期利息
A1: 逾期利息=剩余本金*24%/12*逾期期数 | F1: 绿色为手工填写
A2: 逾期利息=剩余本金*17%/12*逾期期数
A3: 剩余本金 | B3: 利率 | C3: 12个月 | D3: 逾期期数 | E3: 逾期利息
A4: 176284.8 | B4: 0.24 | C4: 12 | D4: 1 | E4: =A4*B4/C4*D4 -> 3525.6959
A5: 176284.8 | B5: 0.17 | C5: 12 | D5: 1 | E5: =A5*B5/C5*D5 -> 2497.3679

Sheet 减免计算
B1: 合同金额 | C1: 实际到账 | D1: 分期总数 | E1: 每期金额 | F1: 2020.8.19及之前期数 | G1: 2020.8.20及之后期数 | H1: 已还期数 | I1: 未还期数 | J1: 逾期 | K1: 应付利息 | L1: 结果
A2: 减免最小值 | B2: =客户方案计算表!E4*36 -> 219890.88 | C2: =客户方案计算表!B4 -> 150000 | D2: 36 | E2: =客户方案计算表!E4 -> 6108.08 | F2: 10 | G2: 26 | H2: 10 | I2: 26 | J2: 0 | K2: =客户方案计算表!D41+客户方案计算表!J41 -> 47124.377 | L2: =B2-C2-K2 -> 22766.503
A4: 减免最大值 | B4: =客户方案计算表!E4*36 -> 219890.88 | C4: =客户方案计算表!B4 -> 150000 | D4: 36 | E4: =客户方案计算表!E4 -> 6108.08 | F4: 10 | G4: 26 | H4: 10 | I4: 26 | J4: 0 | K4: =客户方案计算表!D41 -> 27048.191 | L4: =B4-C4-K4 -> 42842.689
A6: 计算逻辑： 最大减免=合同金额-到账金额-应付利息 合同金额=每期还款*总期数 应付利息=到账金额*24%*（合同签订日期至2020年8月20日的期数）+到账金额*17*（2020年8月20日至客户最后一次还款那个月的期数） 最小减免=合同金额-到账金额-应付利息 应付利息=到账金额*24%*（合同签订日期至2020年8月20日的期数）+到账金额*17*（36-（合同签订日期至2020年8月20日的期数））
A13: 最大减免=合同金额-已还金额-剩余本金 合同金额=每期还款*总期数 已还金额=每期还款*还款期数 当期剩余本金=实际到账金额-应付利息-冲销本金 当期应付利息=剩余本金*24%/12 剩余本金需要逐笔核减计算得出
A22: 最小减免=合同金额-已还金额-剩余本金-剩余法定利息 合同金额=每期还款*总期数 已还金额=每期还款*还款期数 剩余本金=实际到账金额-应付利息-冲销本金 当期应付利息=剩余本金*24%/12 剩余本金需要逐笔核减计算得出 当期剩余法定利息=剩余本金*17%/12 剩余本金需要逐笔核减计算得出

Sheet Sheet1
